<?xml version='1.0'?>
<sdf version='1.8'>
  <world name='default'>
    <model name='ParentModel'>
      <frame name='ChildModel::__model__' attached_to='ChildModel::L1'>
        <pose relative_to='__model__'>1 0 1 0 -0 0</pose>
      </frame>
      <link name='ChildModel::L1'>
        <pose relative_to='ChildModel::__model__'>0 1 0 0 -0 0</pose>
        <visual name='v1'>
          <geometry>
            <sphere>
              <radius>0.1</radius>
            </sphere>
          </geometry>
        </visual>
      </link>
      <link name='ChildModel::L2'>
        <pose relative_to='ChildModel::__model__'>0 0 0 0 -0 0</pose>
      </link>
      <joint name='ChildModel::J1' type='revolute'>
        <parent>ChildModel::L1</parent>
        <child>ChildModel::L2</child>
      </joint>
    </model>
    <gravity>0 0 -9.8</gravity>
    <magnetic_field>6e-06 2.3e-05 -4.2e-05</magnetic_field>
    <atmosphere type='adiabatic'/>
    <physics type='ode'>
      <max_step_size>0.001</max_step_size>
      <real_time_factor>1</real_time_factor>
      <real_time_update_rate>1000</real_time_update_rate>
    </physics>
    <scene>
      <ambient>0.4 0.4 0.4 1</ambient>
      <background>0.7 0.7 0.7 1</background>
      <shadows>1</shadows>
    </scene>
  </world>
</sdf>
